Workbook
Name DupCount: SUMPRODUCT((TFA_Assign<>"")*(COUNTIF(TFA_Assign,TFA_Assign)+COUNTIF(TFB_Assign,TFA_Assign)>1))
Name TFA_Assign: 'Task Force A'!$C$5:$C$200
Name TFB_Assign: 'Task Force B'!$C$5:$C$200

Sheet Players
A1: Player Name | B1: Rank | C1: Overall Power | D1: Squad 1 Power (future) | E1: Squad 2 Power (future) | F1: Squad 3 Power (future) | G1: Squad 4 Power (future) | H1: Total Wall Power
A2: DefenestranatorX | B2: R5 | C2: 37.3 | D2: 13.79 | E2: 7.11 | F2: 6.32 | G2: 8.36 | H2: =G2+F2+E2+D2 -> 35.58 | J2: 20
A3: Cdub81 | B3: R4 | C3: 36 | D3: 9.8 | E3: 6.55 | F3: 5.58 | H3: =G3+F3+E3+D3 -> 21.93
A4: Sebby5683 | B4: R4 | C4: 45.1 | D4: 13.59 | E4: 8.55 | F4: 7.39 | G4: 8.96 | H4: =G4+F4+E4+D4 -> 38.49
A5: Gotchakwik | B5: R4 | C5: 41.5 | D5: 10.85 | E5: 6.81 | F5: 6.15 | H5: =G5+F5+E5+D5 -> 23.81
A6: Perky Petunia | B6: R4 | C6: 62.3 | D6: 13.64 | E6: 8.79 | F6: 8.64 | G6: 7.57 | H6: =G6+F6+E6+D6 -> 38.64
A7: PleaseBeNice | B7: R4 | C7: 49.7 | D7: 12.71 | E7: 7.73 | F7: 7.55 | G7: 6.3 | H7: =G7+F7+E7+D7 -> 34.29
A8: xEibon | B8: R4 | C8: 34.7 | D8: 11.68 | E8: 6.17 | F8: 5.52 | G8: 8.44 | H8: =G8+F8+E8+D8 -> 31.81
A9: PlagusStein | B9: R4 | C9: 65.6 | D9: 16.58 | E9: 10.4 | F9: 10.4 | G9: 10.47 | H9: =G9+F9+E9+D9 -> 47.85
A10: Zapatista09 | B10: R4 | C10: 35.7 | D10: 9.9 | E10: 6.65 | F10: 5.18 | H10: =G10+F10+E10+D10 -> 21.73
A11: SlipumDeadHead | B11: R4 | C11: 31.7 | D11: 10.28 | E11: 4.49 | F11: 4.44 | G11: 7.24 | H11: =G11+F11+E11+D11 -> 26.45
A12: Auti111 | B12: R4 | C12: 44.7 | D12: 9.84 | E12: 7.35 | F12: 5.91 | G12: 5.16 | H12: =G12+F12+E12+D12 -> 28.26
A13: champ234 | B13: R3 | C13: 44.7 | H13: =G13+F13+E13+D13 -> 0
A14: Patrick t | B14: R3 | C14: 29.1 | H14: =G14+F14+E14+D14 -> 0
A15: Artorias of TheAbyss | B15: R3 | C15: 26.9 | D15: 7.9 | E15: 4.27 | F15: 3.67 | H15: =G15+F15+E15+D15 -> 15.84
A16: xxxxxxy5 | B16: R3 | C16: 39.5 | D16: 10.92 | E16: 7.02 | F16: 6.27 | H16: =G16+F16+E16+D16 -> 24.21
A17: MelaniaAaa | B17: R3 | C17: 26.2 | D17: 6.54 | E17: 6.34 | F17: 5.37 | G17: 4.5 | H17: =G17+F17+E17+D17 -> 22.75
A18: Cowanjo | B18: R3 | C18: 55.6 | D18: 11.51 | E18: 7.94 | F18: 6.62 | G18: 7.21 | H18: =G18+F18+E18+D18 -> 33.28
A19: cassuhhdee | B19: R3 | C19: 23.8 | H19: =G19+F19+E19+D19 -> 0
A20: Neron Cr | B20: R3 | C20: 41.3 | H20: =G20+F20+E20+D20 -> 0
A21: Hydroplanist | B21: R3 | C21: 45.3 | D21: 9.11 | E21: 6.37 | F21: 6.06 | H21: =G21+F21+E21+D21 -> 21.54
A22: Jleehank | B22: R3 | C22: 40.9 | D22: 10.65 | E22: 6.84 | F22: 6.34 | G22: 5.56 | H22: =G22+F22+E22+D22 -> 29.39
A23: ShadowFOX | B23: R3 | C23: 21.6 | H23: =G23+F23+E23+D23 -> 0
A24: WGCSFV | B24: R3 | C24: 40.5 | D24: 9.69 | E24: 6.38 | F24: 5.53 | G24: 5.38 | H24: =G24+F24+E24+D24 -> 26.98
A25: WiseWordz | B25: R3 | C25: 30.7 | D25: 9.14 | E25: 6.79 | F25: 5.6 | H25: =G25+F25+E25+D25 -> 21.53
A26: K Hole | B26: R3 | C26: 36.1 | D26: 9.39 | E26: 5.98 | F26: 7.7 | G26: 7.73 | H26: =G26+F26+E26+D26 -> 30.8
A27: EAlon | B27: R3 | C27: 29.9 | D27: 9.39 | E27: 5.23 | F27: 4.64 | H27: =G27+F27+E27+D27 -> 19.26
A28: Moon Beast | B28: R3 | C28: 28.2 | D28: 7.63 | E28: 6.09 | F28: 4.91 | H28: =G28+F28+E28+D28 -> 18.63
A29: Mr 3 point 75 | B29: R3 | C29: 36.9 | H29: =G29+F29+E29+D29 -> 0
A30: Veneciano II | B30: R3 | C30: 75.1 | D30: 15.57 | E30: 13.65 | F30: 11.53 | G30: 8.97 | H30: =G30+F30+E30+D30 -> 49.72
A31: Action Jackson 59 | B31: R3 | C31: 29.6 | H31: =G31+F31+E31+D31 -> 0
A32: Lostinthewoods | B32: R3 | C32: 25.1 | H32: =G32+F32+E32+D32 -> 0
A33: King Kong SOS | B33: R3 | C33: 35.4 | D33: 12.44 | E33: 8.03 | F33: 6.53 | H33: =G33+F33+E33+D33 -> 27
A34: Tomsin72 | B34: R3 | C34: 29 | D34: 7.05 | E34: 5.41 | F34: 4.46 | H34: =G34+F34+E34+D34 -> 16.92
A35: Kor Pepper | B35: R3 | C35: 30.1 | D35: 10.41 | E35: 6.79 | F35: 6.2 | H35: =G35+F35+E35+D35 -> 23.4
A36: Great Obliterator | B36: R3 | C36: 30 | H36: =G36+F36+E36+D36 -> 0
A37: ZAlon | B37: R3 | C37: 17.9 | H37: =G37+F37+E37+D37 -> 0
A38: 브룩햄더슈 | B38: R3 | C38: 37.7 | H38: =G38+F38+E38+D38 -> 0
A39: rsltid | B39: R3 | C39: 37.7 | H39: =G39+F39+E39+D39 -> 0
A40: FRoldo | B40: R3 | C40: 31.2 | D40: 9.07 | E40: 5.47 | F40: 4.41 | H40: =G40+F40+E40+D40 -> 18.95
...

Sheet Task Force A
A1: Task Force A — Squad Builder
A2: Total Task Force Power | B2: =SUM(D5:D200) -> 2179.2
A3: Notes | B3: Select players from dropdowns. Power pulls from Players sheet (Overall Power). Duplicate players highlight red.
A4: Squad | B4: Slot | C4: Player | D4: Overall Power (M) | E4: Member Type
A5: Hospital Squad
B6: Strategist | C6: Bottled In Bond | D6: =IFERROR(VLOOKUP(C6,Players!$A:$C,3,FALSE),0) -> 0 | E6: Strategist
B7: Full-time 1 | C7: Jagb2011 | D7: =IFERROR(VLOOKUP(C7,Players!$A:$C,3,FALSE),0) -> 38 | E7: Full-time
B8: Full-time 2 | C8: Artorias of TheAbyss | D8: =IFERROR(VLOOKUP(C8,Players!$A:$C,3,FALSE),0) -> 26.9 | E8: Full-time
B9: Full-time 3 | C9: WGCSFV | D9: =IFERROR(VLOOKUP(C9,Players!$A:$C,3,FALSE),0) -> 40.5 | E9: Full-time
B10: Flex 1 | C10: Rotrotomeo | D10: =IFERROR(VLOOKUP(C10,Players!$A:$C,3,FALSE),0) -> 39.8 | E10: Flex
B11: Flex 2 | C11: Jleehank | D11: =IFERROR(VLOOKUP(C11,Players!$A:$C,3,FALSE),0) -> 40.9 | E11: Flex
B12: Squad Total | D12: =SUM(D6:D11) -> 186.1
A14: Oil Squad
B15: Strategist | C15: xEibon | D15: =IFERROR(VLOOKUP(C15,Players!$A:$C,3,FALSE),0) -> 34.7 | E15: Strategist
B16: Full-time 1 | C16: xxxxxxy5 | D16: =IFERROR(VLOOKUP(C16,Players!$A:$C,3,FALSE),0) -> 39.5 | E16: Full-time
B17: Full-time 2 | C17: Kor Pepper | D17: =IFERROR(VLOOKUP(C17,Players!$A:$C,3,FALSE),0) -> 30.1 | E17: Full-time
B18: Full-time 3 | C18: 브룩햄더슈 | D18: =IFERROR(VLOOKUP(C18,Players!$A:$C,3,FALSE),0) -> 37.7 | E18: Full-time
B19: Squad Total | D19: =SUM(D15:D18) -> 142
A21: Science & Info Squad
B22: Strategist | C22: Mr 3 point 75 | D22: =IFERROR(VLOOKUP(C22,Players!$A:$C,3,FALSE),0) -> 36.9 | E22: Strategist
B23: Full-time 1 | C23: Hippie Mike | D23: =IFERROR(VLOOKUP(C23,Players!$A:$C,3,FALSE),0) -> 51 | E23: Full-time
B24: Full-time 2 | C24: Zombie Slayer 64 | D24: =IFERROR(VLOOKUP(C24,Players!$A:$C,3,FALSE),0) -> 27.3 | E24: Full-time
B25: Full-time 3 | C25: soldado006 | D25: =IFERROR(VLOOKUP(C25,Players!$A:$C,3,FALSE),0) -> 35.5 | E25: Full-time
B26: Flex 1 | C26: PleaseBeNice | D26: =IFERROR(VLOOKUP(C26,Players!$A:$C,3,FALSE),0) -> 49.7 | E26: Flex
B27: Squad Total | D27: =SUM(D22:D26) -> 200.4
A29: Roaming Squad
B30: Full-time 1 | C30: King Kong SOS | D30: =IFERROR(VLOOKUP(C30,Players!$A:$C,3,FALSE),0) -> 35.4 | E30: Full-time
B31: Full-time 2 | C31: Sebby5683 | D31: =IFERROR(VLOOKUP(C31,Players!$A:$C,3,FALSE),0) -> 45.1 | E31: Full-time
B32: Full-time 3 | C32: PlagusStein | D32: =IFERROR(VLOOKUP(C32,Players!$A:$C,3,FALSE),0) -> 65.6 | E32: Full-time
B33: Full-time 4 | C33: DefenestranatorX | D33: =IFERROR(VLOOKUP(C33,Players!$A:$C,3,FALSE),0) -> 37.3 | E33: Full-time
B34: Full-time 5 | C34: Perky Petunia | D34: =IFERROR(VLOOKUP(C34,Players!$A:$C,3,FALSE),0) -> 62.3 | E34: Full-time
B35: Squad Total | D35: =SUM(D30:D34) -> 245.7
A37: Substitutes
B38: Sub 1 | C38: Cdub81 | D38: =IFERROR(VLOOKUP(C38,Players!$A:$C,3,FALSE),0) -> 36 | E38: Sub
B39: Sub 2 | C39: Zapatista09 | D39: =IFERROR(VLOOKUP(C39,Players!$A:$C,3,FALSE),0) -> 35.7 | E39: Sub
B40: Sub 3 | C40: Frainho | D40: =IFERROR(VLOOKUP(C40,Players!$A:$C,3,FALSE),0) -> 31.5 | E40: Sub
B41: Sub 4 | C41: 파파로야 | D41: =IFERROR(VLOOKUP(C41,Players!$A:$C,3,FALSE),0) -> 30.3 | E41: Sub
B42: Sub 5 | C42: Ruby PR | D42: =IFERROR(VLOOKUP(C42,Players!$A:$C,3,FALSE),0) -> 34.2 | E42: Sub
B43: Sub 6 | C43: Ace 664 | D43: =IFERROR(VLOOKUP(C43,Players!$A:$C,3,FALSE),0) -> 0 | E43: Sub
B44: Sub 7 | C44: Auti111 | D44: =IFERROR(VLOOKUP(C44,Players!$A:$C,3,FALSE),0) -> 44.7 | E44: Sub
...

Sheet Task Force B
A1: Task Force B — Squad Builder
A2: Total Task Force Power | B2: =SUM(D5:D200) -> 2013.2
A3: Notes | B3: Select players from dropdowns. Power pulls from Players sheet (Overall Power). Duplicate players highlight red.
A4: Squad | B4: Slot | C4: Player | D4: Overall Power (M) | E4: Member Type
A5: Hospital Squad
B6: Strategist | C6: Scottg62 | D6: =IFERROR(VLOOKUP(C6,Players!$A$2:$C$202,3,FALSE),0) -> 33.2 | E6: Strategist
B7: Full-time 1 | C7: JuanManRiot | D7: =IFERROR(VLOOKUP(C7,Players!$A$2:$C$202,3,FALSE),0) -> 38 | E7: Full-time
B8: Full-time 2 | C8: Patrick t | D8: =IFERROR(VLOOKUP(C8,Players!$A$2:$C$202,3,FALSE),0) -> 29.1 | E8: Full-time
B9: Full-time 3 | C9: LtTally | D9: =IFERROR(VLOOKUP(C9,Players!$A$2:$C$202,3,FALSE),0) -> 24.4 | E9: Full-time
B10: Flex 1 | C10: Great Obliterator | D10: =IFERROR(VLOOKUP(C10,Players!$A$2:$C$202,3,FALSE),0) -> 30 | E10: Flex
B11: Flex 2 | C11: r4iDIJN | D11: =IFERROR(VLOOKUP(C11,Players!$A$2:$C$202,3,FALSE),0) -> 51.5 | E11: Flex
B12: Squad Total | D12: =SUM(D6:D11) -> 206.2
A14: Oil Squad
B15: Strategist | C15: MelaniaAaa | D15: =IFERROR(VLOOKUP(C15,Players!$A$2:$C$202,3,FALSE),0) -> 26.2 | E15: Strategist
B16: Full-time 1 | C16: Budda254 | D16: =IFERROR(VLOOKUP(C16,Players!$A$2:$C$202,3,FALSE),0) -> 25.5 | E16: Full-time
B17: Full-time 2 | C17: IBEWsparky | D17: =IFERROR(VLOOKUP(C17,Players!$A$2:$C$202,3,FALSE),0) -> 30.4 | E17: Full-time
B18: Full-time 3 | C18: kaymack | D18: =IFERROR(VLOOKUP(C18,Players!$A$2:$C$202,3,FALSE),0) -> 32.5 | E18: Full-time
B19: Squad Total | D19: =SUM(D15:D18) -> 114.6
A21: Science & Info Squad
B22: Strategist | C22: WiseWordz | D22: =IFERROR(VLOOKUP(C22,Players!$A$2:$C$202,3,FALSE),0) -> 30.7 | E22: Strategist
B23: Full-time 1 | C23: Asya Go | D23: =IFERROR(VLOOKUP(C23,Players!$A$2:$C$202,3,FALSE),0) -> 33.6 | E23: Full-time
B24: Full-time 2 | C24: GravyOC | D24: =IFERROR(VLOOKUP(C24,Players!$A$2:$C$202,3,FALSE),0) -> 34.5 | E24: Full-time
B25: Full-time 3 | C25: SilentKnight61 | D25: =IFERROR(VLOOKUP(C25,Players!$A$2:$C$202,3,FALSE),0) -> 64.1 | E25: Full-time
B26: Flex 1 | C26: Moon Beast | D26: =IFERROR(VLOOKUP(C26,Players!$A$2:$C$202,3,FALSE),0) -> 28.2 | E26: Flex
B27: Squad Total | D27: =SUM(D22:D26) -> 191.1
A29: Roaming Squad
B30: Full-time 1 | C30: rsltid | D30: =IFERROR(VLOOKUP(C30,Players!$A$2:$C$202,3,FALSE),0) -> 37.7 | E30: Full-time
B31: Full-time 2 | C31: Killin Zombs | D31: =IFERROR(VLOOKUP(C31,Players!$A$2:$C$202,3,FALSE),0) -> 38.4 | E31: Full-time
B32: Full-time 3 | C32: Gotchakwik | D32: =IFERROR(VLOOKUP(C32,Players!$A$2:$C$202,3,FALSE),0) -> 41.5 | E32: Full-time
B33: Full-time 4 | C33: Jeeb1971 | D33: =IFERROR(VLOOKUP(C33,Players!$A$2:$C$202,3,FALSE),0) -> 40.5 | E33: Full-time
B34: Full-time 5 | C34: SlipumDeadHead | D34: =IFERROR(VLOOKUP(C34,Players!$A$2:$C$202,3,FALSE),0) -> 31.7 | E34: Full-time
B35: Squad Total | D35: =SUM(D30:D34) -> 189.8
A37: Substitutes
B38: Sub 1 | C38: Crolll | D38: =IFERROR(VLOOKUP(C38,Players!$A:$C,3,FALSE),0) -> 30.1 | E38: Sub
B39: Sub 2 | C39: Bedis1986 | D39: =IFERROR(VLOOKUP(C39,Players!$A:$C,3,FALSE),0) -> 42.4 | E39: Sub
B40: Sub 3 | C40: BigMacFox | D40: =IFERROR(VLOOKUP(C40,Players!$A:$C,3,FALSE),0) -> 31.5 | E40: Sub
B41: Sub 4 | C41: Amerinda | D41: =IFERROR(VLOOKUP(C41,Players!$A:$C,3,FALSE),0) -> 26.5 | E41: Sub
B42: Sub 5 | C42: G R A N D A O SOS | D42: =IFERROR(VLOOKUP(C42,Players!$A:$C,3,FALSE),0) -> 30.8 | E42: Sub
B43: Sub 6 | C43: DuhStroia | D43: =IFERROR(VLOOKUP(C43,Players!$A:$C,3,FALSE),0) -> 39.9 | E43: Sub
B44: Sub 7 | C44: Aintnothing | D44: =IFERROR(VLOOKUP(C45,Players!$A:$C,3,FALSE),0) -> 51.2 | E44: Sub
...

Sheet Dashboard
A1: Task Force Power Comparison
A2: Task Force | B2: Total Power | C2: Difference vs A
A3: Task Force A | B3: ='Task Force A'!B2 -> 2179.2 | C3: 0
A4: Task Force B | B4: ='Task Force B'!B2 -> 2013.2 | C4: =B4-B3 -> -166
A6: Roster Checks
A7: Any duplicate players across A+B? | B7: =IF(DupCount>0,"YES","NO") -> NO
